2018-04-01 22:57:07,840 INFO: Microblog startup [in /Users/wang/PycharmProjects/microblog-0.12/app/__init__.py:49]
2018-04-01 22:57:25,573 ERROR: Exception on /login [POST] [in /Users/wang/anaconda3/envs/python2/lib/python2.7/site-packages/flask/app.py:1560]
Traceback (most recent call last):
  File "/Users/wang/anaconda3/envs/python2/lib/python2.7/site-packages/flask/app.py", line 1982, in wsgi_app
    response = self.full_dispatch_request()
  File "/Users/wang/anaconda3/envs/python2/lib/python2.7/site-packages/flask/app.py", line 1614, in full_dispatch_request
    rv = self.handle_user_exception(e)
  File "/Users/wang/anaconda3/envs/python2/lib/python2.7/site-packages/flask/app.py", line 1517, in handle_user_exception
    reraise(exc_type, exc_value, tb)
  File "/Users/wang/anaconda3/envs/python2/lib/python2.7/site-packages/flask/app.py", line 1612, in full_dispatch_request
    rv = self.dispatch_request()
  File "/Users/wang/anaconda3/envs/python2/lib/python2.7/site-packages/flask/app.py", line 1598, in dispatch_request
    return self.view_functions[rule.endpoint](**req.view_args)
  File "/Users/wang/PycharmProjects/microblog-0.12/app/routes.py", line 62, in login
    user = User.query.filter_by(username=form.username.data).first()
  File "/Users/wang/anaconda3/envs/python2/lib/python2.7/site-packages/sqlalchemy/orm/query.py", line 2789, in first
    ret = list(self[0:1])
  File "/Users/wang/anaconda3/envs/python2/lib/python2.7/site-packages/sqlalchemy/orm/query.py", line 2581, in __getitem__
    return list(res)
  File "/Users/wang/anaconda3/envs/python2/lib/python2.7/site-packages/sqlalchemy/orm/query.py", line 2889, in __iter__
    return self._execute_and_instances(context)
  File "/Users/wang/anaconda3/envs/python2/lib/python2.7/site-packages/sqlalchemy/orm/query.py", line 2912, in _execute_and_instances
    result = conn.execute(querycontext.statement, self._params)
  File "/Users/wang/anaconda3/envs/python2/lib/python2.7/site-packages/sqlalchemy/engine/base.py", line 948, in execute
    return meth(self, multiparams, params)
  File "/Users/wang/anaconda3/envs/python2/lib/python2.7/site-packages/sqlalchemy/sql/elements.py", line 269, in _execute_on_connection
    return connection._execute_clauseelement(self, multiparams, params)
  File "/Users/wang/anaconda3/envs/python2/lib/python2.7/site-packages/sqlalchemy/engine/base.py", line 1060, in _execute_clauseelement
    compiled_sql, distilled_params
  File "/Users/wang/anaconda3/envs/python2/lib/python2.7/site-packages/sqlalchemy/engine/base.py", line 1200, in _execute_context
    context)
  File "/Users/wang/anaconda3/envs/python2/lib/python2.7/site-packages/sqlalchemy/engine/base.py", line 1413, in _handle_dbapi_exception
    exc_info
  File "/Users/wang/anaconda3/envs/python2/lib/python2.7/site-packages/sqlalchemy/util/compat.py", line 203, in raise_from_cause
    reraise(type(exception), exception, tb=exc_tb, cause=cause)
  File "/Users/wang/anaconda3/envs/python2/lib/python2.7/site-packages/sqlalchemy/engine/base.py", line 1193, in _execute_context
    context)
  File "/Users/wang/anaconda3/envs/python2/lib/python2.7/site-packages/sqlalchemy/engine/default.py", line 507, in do_execute
    cursor.execute(statement, parameters)
OperationalError: (sqlite3.OperationalError) no such table: user [SQL: u'SELECT user.id AS user_id, user.username AS user_username, user.email AS user_email, user.password_hash AS user_password_hash, user.about_me AS user_about_me, user.last_seen AS user_last_seen \nFROM user \nWHERE user.username = ?\n LIMIT ? OFFSET ?'] [parameters: (u'A0111785@u.nus.edu', 1, 0)] (Background on this error at: http://sqlalche.me/e/e3q8)
2018-04-01 22:57:48,850 ERROR: Exception on /register [POST] [in /Users/wang/anaconda3/envs/python2/lib/python2.7/site-packages/flask/app.py:1560]
Traceback (most recent call last):
  File "/Users/wang/anaconda3/envs/python2/lib/python2.7/site-packages/flask/app.py", line 1982, in wsgi_app
    response = self.full_dispatch_request()
  File "/Users/wang/anaconda3/envs/python2/lib/python2.7/site-packages/flask/app.py", line 1614, in full_dispatch_request
    rv = self.handle_user_exception(e)
  File "/Users/wang/anaconda3/envs/python2/lib/python2.7/site-packages/flask/app.py", line 1517, in handle_user_exception
    reraise(exc_type, exc_value, tb)
  File "/Users/wang/anaconda3/envs/python2/lib/python2.7/site-packages/flask/app.py", line 1612, in full_dispatch_request
    rv = self.dispatch_request()
  File "/Users/wang/anaconda3/envs/python2/lib/python2.7/site-packages/flask/app.py", line 1598, in dispatch_request
    return self.view_functions[rule.endpoint](**req.view_args)
  File "/Users/wang/PycharmProjects/microblog-0.12/app/routes.py", line 85, in register
    if form.validate_on_submit():
  File "/Users/wang/anaconda3/envs/python2/lib/python2.7/site-packages/flask_wtf/form.py", line 101, in validate_on_submit
    return self.is_submitted() and self.validate()
  File "/Users/wang/anaconda3/envs/python2/lib/python2.7/site-packages/wtforms/form.py", line 310, in validate
    return super(Form, self).validate(extra)
  File "/Users/wang/anaconda3/envs/python2/lib/python2.7/site-packages/wtforms/form.py", line 152, in validate
    if not field.validate(self, extra):
  File "/Users/wang/anaconda3/envs/python2/lib/python2.7/site-packages/wtforms/fields/core.py", line 204, in validate
    stop_validation = self._run_validation_chain(form, chain)
  File "/Users/wang/anaconda3/envs/python2/lib/python2.7/site-packages/wtforms/fields/core.py", line 224, in _run_validation_chain
    validator(form, self)
  File "/Users/wang/PycharmProjects/microblog-0.12/app/forms.py", line 25, in validate_username
    user = User.query.filter_by(username=username.data).first()
  File "/Users/wang/anaconda3/envs/python2/lib/python2.7/site-packages/sqlalchemy/orm/query.py", line 2789, in first
    ret = list(self[0:1])
  File "/Users/wang/anaconda3/envs/python2/lib/python2.7/site-packages/sqlalchemy/orm/query.py", line 2581, in __getitem__
    return list(res)
  File "/Users/wang/anaconda3/envs/python2/lib/python2.7/site-packages/sqlalchemy/orm/query.py", line 2889, in __iter__
    return self._execute_and_instances(context)
  File "/Users/wang/anaconda3/envs/python2/lib/python2.7/site-packages/sqlalchemy/orm/query.py", line 2912, in _execute_and_instances
    result = conn.execute(querycontext.statement, self._params)
  File "/Users/wang/anaconda3/envs/python2/lib/python2.7/site-packages/sqlalchemy/engine/base.py", line 948, in execute
    return meth(self, multiparams, params)
  File "/Users/wang/anaconda3/envs/python2/lib/python2.7/site-packages/sqlalchemy/sql/elements.py", line 269, in _execute_on_connection
    return connection._execute_clauseelement(self, multiparams, params)
  File "/Users/wang/anaconda3/envs/python2/lib/python2.7/site-packages/sqlalchemy/engine/base.py", line 1060, in _execute_clauseelement
    compiled_sql, distilled_params
  File "/Users/wang/anaconda3/envs/python2/lib/python2.7/site-packages/sqlalchemy/engine/base.py", line 1200, in _execute_context
    context)
  File "/Users/wang/anaconda3/envs/python2/lib/python2.7/site-packages/sqlalchemy/engine/base.py", line 1413, in _handle_dbapi_exception
    exc_info
  File "/Users/wang/anaconda3/envs/python2/lib/python2.7/site-packages/sqlalchemy/util/compat.py", line 203, in raise_from_cause
    reraise(type(exception), exception, tb=exc_tb, cause=cause)
  File "/Users/wang/anaconda3/envs/python2/lib/python2.7/site-packages/sqlalchemy/engine/base.py", line 1193, in _execute_context
    context)
  File "/Users/wang/anaconda3/envs/python2/lib/python2.7/site-packages/sqlalchemy/engine/default.py", line 507, in do_execute
    cursor.execute(statement, parameters)
OperationalError: (sqlite3.OperationalError) no such table: user [SQL: u'SELECT user.id AS user_id, user.username AS user_username, user.email AS user_email, user.password_hash AS user_password_hash, user.about_me AS user_about_me, user.last_seen AS user_last_seen \nFROM user \nWHERE user.username = ?\n LIMIT ? OFFSET ?'] [parameters: (u'apple', 1, 0)] (Background on this error at: http://sqlalche.me/e/e3q8)
2018-04-01 22:58:31,599 INFO: Microblog startup [in /Users/wang/PycharmProjects/microblog-0.12/app/__init__.py:49]
2018-04-01 22:58:35,580 INFO: Microblog startup [in /Users/wang/PycharmProjects/microblog-0.12/app/__init__.py:49]
2018-04-01 22:59:47,914 INFO: Microblog startup [in /Users/wang/PycharmProjects/microblog-0.12/app/__init__.py:49]
2018-04-01 23:01:37,297 INFO: Microblog startup [in /Users/wang/PycharmProjects/microblog-0.12/app/__init__.py:49]
2018-04-01 23:03:20,621 INFO: Microblog startup [in /Users/wang/PycharmProjects/microblog-0.12/app/__init__.py:49]
2018-04-01 23:03:25,271 INFO: Microblog startup [in /Users/wang/PycharmProjects/microblog-0.12/app/__init__.py:49]
2018-04-01 23:11:28,697 INFO: Microblog startup [in /Users/wang/PycharmProjects/microblog-0.12/app/__init__.py:49]
2018-04-01 23:12:16,428 INFO: Microblog startup [in /Users/wang/PycharmProjects/microblog-0.12/app/__init__.py:49]
2018-04-01 23:13:03,943 INFO: Microblog startup [in /Users/wang/PycharmProjects/microblog-0.12/app/__init__.py:49]
2018-04-01 23:13:14,921 INFO: Microblog startup [in /Users/wang/PycharmProjects/microblog-0.12/app/__init__.py:49]
2018-04-01 23:13:45,823 INFO: Microblog startup [in /Users/wang/PycharmProjects/microblog-0.12/app/__init__.py:49]
2018-04-01 23:14:10,234 INFO: Microblog startup [in /Users/wang/PycharmProjects/microblog-0.12/app/__init__.py:49]
2018-04-01 23:14:33,863 INFO: Microblog startup [in /Users/wang/PycharmProjects/microblog-0.12/app/__init__.py:49]
2018-04-01 23:14:47,855 INFO: Microblog startup [in /Users/wang/PycharmProjects/microblog-0.12/app/__init__.py:49]
2018-04-01 23:29:49,686 INFO: Microblog startup [in /Users/wang/PycharmProjects/microblog-0.12/app/__init__.py:49]
2018-04-01 23:36:17,332 INFO: Microblog startup [in /Users/wang/PycharmProjects/microblog-0.12/app/__init__.py:49]
2018-04-01 23:42:07,348 INFO: Microblog startup [in /Users/wang/PycharmProjects/microblog-0.12/app/__init__.py:49]
